---
title: Die Throw-Anweisung kann außerhalb einer Catch-Anweisung oder innerhalb einer Finally-Anweisung den Operanden nicht auslassen.
ms.date: 07/20/2015
f1_keywords:
- vbc30666
- bc30666
helpviewer_keywords:
- BC30666
ms.assetid: a208a6ea-0e36-4bf1-8984-4de1a0e38a2a
ms.openlocfilehash: 17e7817c608e9c3513e0320b62f42410613f33b0
ms.sourcegitcommit: 9b552addadfb57fab0b9e7852ed4f1f1b8a42f8e
ms.translationtype: MT
ms.contentlocale: de-DE
ms.lasthandoff: 04/23/2019
ms.locfileid: "61666039"
---
# <a name="throw-statement-cannot-omit-operand-outside-a-catch-statement-or-inside-a-finally-statement"></a>Die Throw-Anweisung kann außerhalb einer Catch-Anweisung oder innerhalb einer Finally-Anweisung den Operanden nicht auslassen.
`Throw` -Anweisungen außerhalb einer `Catch` -Anweisung müssen den Namen eines Ausnahmeobjekts angeben.  
  
 **Fehler-ID:** BC30666  
  
## <a name="to-correct-this-error"></a>So beheben Sie diesen Fehler  
  
1. Geben Sie den Namen eines von `System.Exception`abgeleiteten Ausnahmeobjekts an.  
  
2. Strukturieren Sie den Code neu, damit sich die `Throw` -Anweisung innerhalb eines `Catch` -Blocks befindet.  
  
## <a name="see-also"></a>Siehe auch

- [Throw-Anweisung](../../visual-basic/language-reference/statements/throw-statement.md)
- [Try...Catch...Finally-Anweisung](../../visual-basic/language-reference/statements/try-catch-finally-statement.md)
- <xref:System.Exception?displayProperty=nameWithType>
- [Behandeln und Auslösen von Ausnahmen in .NET](../../standard/exceptions/index.md)
